Workbook

Sheet PONTUACAO
A1: PARTICIPANTE | D1: SERGIO | H1: FELIPE | L1: DANILO | P1: EDINHO | T1: NINO | X1: CARLÃO | AB1: GRANDE | AF1: ENIO | AJ1: UEDA | AN1: MICA | AR1: TURATI | AV1: ALEXANDRE | AZ1: - | BD1: - | BH1: - | BL1: - | BP1: - | BT1: -
A2: DATA | B2: QTDE | C2: $ | D2: PGTO | E2: POS | F2: ALMA | G2: PONT | H2: PGTO | I2: POS | J2: ALMA | K2: PONT | L2: PGTO | M2: POS | N2: ALMA | O2: PONT | P2: PGTO | Q2: POS | R2: ALMA | S2: PONT | T2: PGTO | U2: POS | V2: ALMA | W2: PONT | X2: PGTO | Y2: POS | Z2: ALMA | AA2: PONT | AB2: PGTO | AC2: POS | AD2: ALMA | AE2: PONT | AF2: PGTO | AG2: POS | AH2: ALMA | AI2: PONT | AJ2: PGTO | AK2: POS | AL2: ALMA | AM2: PONT | AN2: PGTO | AO2: POS | AP2: ALMA | AQ2: PONT | AR2: PGTO | AS2: POS | AT2: ALMA | AU2: PONT | AV2: PGTO | AW2: POS | AX2: ALMA | AY2: PONT | AZ2: PGTO | BA2: POS | BB2: ALMA | BC2: PONT | BD2: PGTO | BE2: POS | BF2: ALMA | BG2: PONT | BH2: PGTO | BI2: POS | BJ2: ALMA | BK2: PONT | BL2: PGTO | BM2: POS | BN2: ALMA | BO2: PONT | BP2: PGTO | BQ2: POS | BR2: ALMA | BS2: PONT | BT2: PGTO | BU2: POS | BV2: ALMA | BW2: PONT
A3: 46056 | B3: =IF(E3="-",0,1)+IF(I3="-",0,1)+IF(M3="-",0,1)+IF(Q3="-",0,1)+IF(U3="-",0,1)+IF(Y3="-",0,1)+IF(AC3="-",0,1)+IF(AG3="-",0,1)+IF(AK3="-",0,1)+IF(AO3="-",0,1)+IF(AS3="-",0,1)+IF(AW3="-",0,1)+IF(BA3="-",0,1)+IF(BE3="-",0,1)+IF(BI3="-",0,1)+IF(BM3="-",0,1)+IF(BQ3="-",0,1)+IF(BU3="-",0,1) -> 9 | C3: =(B3*$D$44)-IF(B3 >0,30,0) -> 60 | D3: S | E3: 1 | F3: 5 | G3: =VLOOKUP(E3,$A$27:$E$43,2,FALSE)+(IF(F3="-",0,F3*1)) -> 30 | H3: S | I3: 5 | J3: - | K3: =VLOOKUP(I3,$A$27:$E$43,2,FALSE)+(IF(J3="-",0,J3*1)) -> 10 | L3: S | M3: 4 | N3: - | O3: =VLOOKUP(M3,$A$27:$E$43,2,FALSE)+(IF(N3="-",0,N3*1)) -> 12 | P3: S | Q3: 2 | R3: 2 | S3: =VLOOKUP(Q3,$A$27:$E$43,2,FALSE)+(IF(R3="-",0,R3*1)) -> 20 | T3: S | U3: 6 | V3: - | W3: =VLOOKUP(U3,$A$27:$E$43,2,FALSE)+(IF(V3="-",0,V3*1)) -> 8 | X3: S | Y3: 8 | Z3: - | AA3: =VLOOKUP(Y3,$A$27:$E$43,2,FALSE)+(IF(Z3="-",0,Z3*1)) -> 4 | AB3: S | AC3: 9 | AD3: - | AE3: =VLOOKUP(AC3,$A$27:$E$43,2,FALSE)+(IF(AD3="-",0,AD3*1)) -> 2 | AF3: S | AG3: 3 | AH3: 2 | AI3: =VLOOKUP(AG3,$A$27:$E$43,2,FALSE)+(IF(AH3="-",0,AH3*1)) -> 17 | AJ3: S | AK3: 7 | AL3: - | AM3: =VLOOKUP(AK3,$A$27:$E$43,2,FALSE)+(IF(AL3="-",0,AL3*1)) -> 6 | AN3: - | AO3: - | AP3: - | AQ3: =VLOOKUP(AO3,$A$27:$E$43,2,FALSE)+(IF(AP3="-",0,AP3*1)) -> 0 | AR3: - | AS3: - | AT3: - | AU3: =VLOOKUP(AS3,$A$27:$E$43,2,FALSE)+(IF(AT3="-",0,AT3*1)) -> 0 | AV3: - | AW3: - | AX3: - | AY3: =VLOOKUP(AW3,$A$27:$E$43,2,FALSE)+(IF(AX3="-",0,AX3*1)) -> 0 | AZ3: - | BA3: - | BB3: - | BC3: =VLOOKUP(BA3,$A$27:$E$43,2,FALSE)+(IF(BB3="-",0,BB3*1)) -> 0 | BD3: - | BE3: - | BF3: - | BG3: =VLOOKUP(BE3,$A$27:$E$43,2,FALSE)+(IF(BF3="-",0,BF3*1)) -> 0 | BH3: - | BI3: - | BJ3: - | BK3: =VLOOKUP(BI3,$A$27:$E$43,2,FALSE)+(IF(BJ3="-",0,BJ3*1)) -> 0 | BL3: - | BM3: - | BN3: - | BO3: =VLOOKUP(BM3,$A$27:$E$43,2,FALSE)+(IF(BN3="-",0,BN3*1)) -> 0 | BP3: - | BQ3: - | BR3: - | BS3: =VLOOKUP(BQ3,$A$27:$E$43,2,FALSE)+(IF(BR3="-",0,BR3*1)) -> 0 | BT3: - | BU3: - | BV3: - | BW3: =VLOOKUP(BU3,$A$27:$E$43,2,FALSE)+(IF(BV3="-",0,BV3*1)) -> 0
A4: 46063 | B4: =IF(E4="-",0,1)+IF(I4="-",0,1)+IF(M4="-",0,1)+IF(Q4="-",0,1)+IF(U4="-",0,1)+IF(Y4="-",0,1)+IF(AC4="-",0,1)+IF(AG4="-",0,1)+IF(AK4="-",0,1)+IF(AO4="-",0,1)+IF(AS4="-",0,1)+IF(AW4="-",0,1)+IF(BA4="-",0,1)+IF(BE4="-",0,1)+IF(BI4="-",0,1)+IF(BM4="-",0,1)+IF(BQ4="-",0,1)+IF(BU4="-",0,1) -> 9 | C4: =(B4*$D$44)-IF(B4 >0,30,0) -> 60 | D4: S | E4: 4 | F4: - | G4: =VLOOKUP(E4,$A$27:$E$43,2,FALSE)+(IF(F4="-",0,F4*1)) -> 12 | H4: S | I4: 7 | J4: - | K4: =VLOOKUP(I4,$A$27:$E$43,2,FALSE)+(IF(J4="-",0,J4*1)) -> 6 | L4: S | M4: 2 | N4: 3 | O4: =VLOOKUP(M4,$A$27:$E$43,2,FALSE)+(IF(N4="-",0,N4*1)) -> 21 | P4: S | Q4: 1 | R4: 3 | S4: =VLOOKUP(Q4,$A$27:$E$43,2,FALSE)+(IF(R4="-",0,R4*1)) -> 28 | T4: S | U4: 5 | V4: 1 | W4: =VLOOKUP(U4,$A$27:$E$43,2,FALSE)+(IF(V4="-",0,V4*1)) -> 11 | X4: S | Y4: 8 | Z4: - | AA4: =VLOOKUP(Y4,$A$27:$E$43,2,FALSE)+(IF(Z4="-",0,Z4*1)) -> 4 | AB4: S | AC4: 9 | AD4: - | AE4: =VLOOKUP(AC4,$A$27:$E$43,2,FALSE)+(IF(AD4="-",0,AD4*1)) -> 2 | AF4: S | AG4: 6 | AH4: - | AI4: =VLOOKUP(AG4,$A$27:$E$43,2,FALSE)+(IF(AH4="-",0,AH4*1)) -> 8 | AJ4: S | AK4: 2 | AL4: 3 | AM4: =VLOOKUP(AK4,$A$27:$E$43,2,FALSE)+(IF(AL4="-",0,AL4*1)) -> 21 | AN4: - | AO4: - | AP4: - | AQ4: =VLOOKUP(AO4,$A$27:$E$43,2,FALSE)+(IF(AP4="-",0,AP4*1)) -> 0 | AR4: - | AS4: - | AT4: - | AU4: =VLOOKUP(AS4,$A$27:$E$43,2,FALSE)+(IF(AT4="-",0,AT4*1)) -> 0 | AV4: - | AW4: - | AX4: - | AY4: =VLOOKUP(AW4,$A$27:$E$43,2,FALSE)+(IF(AX4="-",0,AX4*1)) -> 0 | AZ4: - | BA4: - | BB4: - | BC4: =VLOOKUP(BA4,$A$27:$E$43,2,FALSE)+(IF(BB4="-",0,BB4*1)) -> 0 | BD4: - | BE4: - | BF4: - | BG4: =VLOOKUP(BE4,$A$27:$E$43,2,FALSE)+(IF(BF4="-",0,BF4*1)) -> 0 | BH4: - | BI4: - | BJ4: - | BK4: =VLOOKUP(BI4,$A$27:$E$43,2,FALSE)+(IF(BJ4="-",0,BJ4*1)) -> 0 | BL4: - | BM4: - | BN4: - | BO4: =VLOOKUP(BM4,$A$27:$E$43,2,FALSE)+(IF(BN4="-",0,BN4*1)) -> 0 | BP4: - | BQ4: - | BR4: - | BS4: =VLOOKUP(BQ4,$A$27:$E$43,2,FALSE)+(IF(BR4="-",0,BR4*1)) -> 0 | BT4: - | BU4: - | BV4: - | BW4: =VLOOKUP(BU4,$A$27:$E$43,2,FALSE)+(IF(BV4="-",0,BV4*1)) -> 0
A5: 46077 | B5: =IF(E5="-",0,1)+IF(I5="-",0,1)+IF(M5="-",0,1)+IF(Q5="-",0,1)+IF(U5="-",0,1)+IF(Y5="-",0,1)+IF(AC5="-",0,1)+IF(AG5="-",0,1)+IF(AK5="-",0,1)+IF(AO5="-",0,1)+IF(AS5="-",0,1)+IF(AW5="-",0,1)+IF(BA5="-",0,1)+IF(BE5="-",0,1)+IF(BI5="-",0,1)+IF(BM5="-",0,1)+IF(BQ5="-",0,1)+IF(BU5="-",0,1) -> 9 | C5: =(B5*$D$44)-IF(B5 >0,30,0) -> 60 | D5: S | E5: 7 | F5: - | G5: =VLOOKUP(E5,$A$27:$E$43,2,FALSE)+(IF(F5="-",0,F5*1)) -> 6 | H5: S | I5: 9 | J5: - | K5: =VLOOKUP(I5,$A$27:$E$43,2,FALSE)+(IF(J5="-",0,J5*1)) -> 2 | L5: S | M5: 1 | N5: 2 | O5: =VLOOKUP(M5,$A$27:$E$43,2,FALSE)+(IF(N5="-",0,N5*1)) -> 27 | P5: S | Q5: 5 | R5: 2 | S5: =VLOOKUP(Q5,$A$27:$E$43,2,FALSE)+(IF(R5="-",0,R5*1)) -> 12 | T5: S | U5: 4 | V5: - | W5: =VLOOKUP(U5,$A$27:$E$43,2,FALSE)+(IF(V5="-",0,V5*1)) -> 12 | X5: - | Y5: - | Z5: - | AA5: =VLOOKUP(Y5,$A$27:$E$43,2,FALSE)+(IF(Z5="-",0,Z5*1)) -> 0 | AB5: S | AC5: 8 | AD5: 1 | AE5: =VLOOKUP(AC5,$A$27:$E$43,2,FALSE)+(IF(AD5="-",0,AD5*1)) -> 5 | AF5: S | AG5: 3 | AH5: 2 | AI5: =VLOOKUP(AG5,$A$27:$E$43,2,FALSE)+(IF(AH5="-",0,AH5*1)) -> 17 | AJ5: S | AK5: 6 | AL5: - | AM5: =VLOOKUP(AK5,$A$27:$E$43,2,FALSE)+(IF(AL5="-",0,AL5*1)) -> 8 | AN5: - | AO5: - | AP5: - | AQ5: =VLOOKUP(AO5,$A$27:$E$43,2,FALSE)+(IF(AP5="-",0,AP5*1)) -> 0 | AR5: S | AS5: 2 | AT5: 2 | AU5: =VLOOKUP(AS5,$A$27:$E$43,2,FALSE)+(IF(AT5="-",0,AT5*1)) -> 20 | AV5: - | AW5: - | AX5: - | AY5: =VLOOKUP(AW5,$A$27:$E$43,2,FALSE)+(IF(AX5="-",0,AX5*1)) -> 0 | AZ5: - | BA5: - | BB5: - | BC5: =VLOOKUP(BA5,$A$27:$E$43,2,FALSE)+(IF(BB5="-",0,BB5*1)) -> 0 | BD5: - | BE5: - | BF5: - | BG5: =VLOOKUP(BE5,$A$27:$E$43,2,FALSE)+(IF(BF5="-",0,BF5*1)) -> 0 | BH5: - | BI5: - | BJ5: - | BK5: =VLOOKUP(BI5,$A$27:$E$43,2,FALSE)+(IF(BJ5="-",0,BJ5*1)) -> 0 | BL5: - | BM5: - | BN5: - | BO5: =VLOOKUP(BM5,$A$27:$E$43,2,FALSE)+(IF(BN5="-",0,BN5*1)) -> 0 | BP5: - | BQ5: - | BR5: - | BS5: =VLOOKUP(BQ5,$A$27:$E$43,2,FALSE)+(IF(BR5="-",0,BR5*1)) -> 0 | BT5: - | BU5: - | BV5: - | BW5: =VLOOKUP(BU5,$A$27:$E$43,2,FALSE)+(IF(BV5="-",0,BV5*1)) -> 0
A6: 46084 | B6: =IF(E6="-",0,1)+IF(I6="-",0,1)+IF(M6="-",0,1)+IF(Q6="-",0,1)+IF(U6="-",0,1)+IF(Y6="-",0,1)+IF(AC6="-",0,1)+IF(AG6="-",0,1)+IF(AK6="-",0,1)+IF(AO6="-",0,1)+IF(AS6="-",0,1)+IF(AW6="-",0,1)+IF(BA6="-",0,1)+IF(BE6="-",0,1)+IF(BI6="-",0,1)+IF(BM6="-",0,1)+IF(BQ6="-",0,1)+IF(BU6="-",0,1) -> 9 | C6: =(B6*$D$44)-IF(B6 >0,30,0) -> 60 | D6: S | E6: 8 | F6: - | G6: =VLOOKUP(E6,$A$27:$E$43,2,FALSE)+(IF(F6="-",0,F6*1)) -> 4 | H6: S | I6: 2 | J6: 3 | K6: =VLOOKUP(I6,$A$27:$E$43,2,FALSE)+(IF(J6="-",0,J6*1)) -> 21 | L6: S | M6: 6 | N6: - | O6: =VLOOKUP(M6,$A$27:$E$43,2,FALSE)+(IF(N6="-",0,N6*1)) -> 8 | P6: S | Q6: 7 | R6: - | S6: =VLOOKUP(Q6,$A$27:$E$43,2,FALSE)+(IF(R6="-",0,R6*1)) -> 6 | T6: S | U6: 9 | V6: - | W6: =VLOOKUP(U6,$A$27:$E$43,2,FALSE)+(IF(V6="-",0,V6*1)) -> 2 | X6: S | Y6: 4 | Z6: - | AA6: =VLOOKUP(Y6,$A$27:$E$43,2,FALSE)+(IF(Z6="-",0,Z6*1)) -> 12 | AB6: S | AC6: 3 | AD6: 3 | AE6: =VLOOKUP(AC6,$A$27:$E$43,2,FALSE)+(IF(AD6="-",0,AD6*1)) -> 18 | AF6: S | AG6: 1 | AH6: 3 | AI6: =VLOOKUP(AG6,$A$27:$E$43,2,FALSE)+(IF(AH6="-",0,AH6*1)) -> 28 | AJ6: S | AK6: 5 | AL6: - | AM6: =VLOOKUP(AK6,$A$27:$E$43,2,FALSE)+(IF(AL6="-",0,AL6*1)) -> 10 | AN6: - | AO6: - | AP6: - | AQ6: =VLOOKUP(AO6,$A$27:$E$43,2,FALSE)+(IF(AP6="-",0,AP6*1)) -> 0 | AR6: - | AS6: - | AT6: - | AU6: =VLOOKUP(AS6,$A$27:$E$43,2,FALSE)+(IF(AT6="-",0,AT6*1)) -> 0 | AV6: - | AW6: - | AX6: - | AY6: =VLOOKUP(AW6,$A$27:$E$43,2,FALSE)+(IF(AX6="-",0,AX6*1)) -> 0 | AZ6: - | BA6: - | BB6: - | BC6: =VLOOKUP(BA6,$A$27:$E$43,2,FALSE)+(IF(BB6="-",0,BB6*1)) -> 0 | BD6: - | BE6: - | BF6: - | BG6: =VLOOKUP(BE6,$A$27:$E$43,2,FALSE)+(IF(BF6="-",0,BF6*1)) -> 0 | BH6: - | BI6: - | BJ6: - | BK6: =VLOOKUP(BI6,$A$27:$E$43,2,FALSE)+(IF(BJ6="-",0,BJ6*1)) -> 0 | BL6: - | BM6: - | BN6: - | BO6: =VLOOKUP(BM6,$A$27:$E$43,2,FALSE)+(IF(BN6="-",0,BN6*1)) -> 0 | BP6: - | BQ6: - | BR6: - | BS6: =VLOOKUP(BQ6,$A$27:$E$43,2,FALSE)+(IF(BR6="-",0,BR6*1)) -> 0 | BT6: - | BU6: - | BV6: - | BW6: =VLOOKUP(BU6,$A$27:$E$43,2,FALSE)+(IF(BV6="-",0,BV6*1)) -> 0
A7: 46091 | B7: =IF(E7="-",0,1)+IF(I7="-",0,1)+IF(M7="-",0,1)+IF(Q7="-",0,1)+IF(U7="-",0,1)+IF(Y7="-",0,1)+IF(AC7="-",0,1)+IF(AG7="-",0,1)+IF(AK7="-",0,1)+IF(AO7="-",0,1)+IF(AS7="-",0,1)+IF(AW7="-",0,1)+IF(BA7="-",0,1)+IF(BE7="-",0,1)+IF(BI7="-",0,1)+IF(BM7="-",0,1)+IF(BQ7="-",0,1)+IF(BU7="-",0,1) -> 9 | C7: =(B7*$D$44)-IF(B7 >0,30,0) -> 60 | D7: S | E7: 1 | F7: 4 | G7: =VLOOKUP(E7,$A$27:$E$43,2,FALSE)+(IF(F7="-",0,F7*1)) -> 29 | H7: S | I7: 9 | J7: - | K7: =VLOOKUP(I7,$A$27:$E$43,2,FALSE)+(IF(J7="-",0,J7*1)) -> 2 | L7: S | M7: 7 | N7: - | O7: =VLOOKUP(M7,$A$27:$E$43,2,FALSE)+(IF(N7="-",0,N7*1)) -> 6 | P7: S | Q7: 3 | R7: 1 | S7: =VLOOKUP(Q7,$A$27:$E$43,2,FALSE)+(IF(R7="-",0,R7*1)) -> 16 | T7: S | U7: 8 | V7: - | W7: =VLOOKUP(U7,$A$27:$E$43,2,FALSE)+(IF(V7="-",0,V7*1)) -> 4 | X7: S | Y7: 6 | Z7: 1 | AA7: =VLOOKUP(Y7,$A$27:$E$43,2,FALSE)+(IF(Z7="-",0,Z7*1)) -> 9 | AB7: S | AC7: 5 | AD7: - | AE7: =VLOOKUP(AC7,$A$27:$E$43,2,FALSE)+(IF(AD7="-",0,AD7*1)) -> 10 | AF7: S | AG7: 4 | AH7: - | AI7: =VLOOKUP(AG7,$A$27:$E$43,2,FALSE)+(IF(AH7="-",0,AH7*1)) -> 12 | AJ7: S | AK7: 2 | AL7: 3 | AM7: =VLOOKUP(AK7,$A$27:$E$43,2,FALSE)+(IF(AL7="-",0,AL7*1)) -> 21 | AN7: - | AO7: - | AP7: - | AQ7: =VLOOKUP(AO7,$A$27:$E$43,2,FALSE)+(IF(AP7="-",0,AP7*1)) -> 0 | AR7: - | AS7: - | AT7: - | AU7: =VLOOKUP(AS7,$A$27:$E$43,2,FALSE)+(IF(AT7="-",0,AT7*1)) -> 0 | AV7: - | AW7: - | AX7: - | AY7: =VLOOKUP(AW7,$A$27:$E$43,2,FALSE)+(IF(AX7="-",0,AX7*1)) -> 0 | AZ7: - | BA7: - | BB7: - | BC7: =VLOOKUP(BA7,$A$27:$E$43,2,FALSE)+(IF(BB7="-",0,BB7*1)) -> 0 | BD7: - | BE7: - | BF7: - | BG7: =VLOOKUP(BE7,$A$27:$E$43,2,FALSE)+(IF(BF7="-",0,BF7*1)) -> 0 | BH7: - | BI7: - | BJ7: - | BK7: =VLOOKUP(BI7,$A$27:$E$43,2,FALSE)+(IF(BJ7="-",0,BJ7*1)) -> 0 | BL7: - | BM7: - | BN7: - | BO7: =VLOOKUP(BM7,$A$27:$E$43,2,FALSE)+(IF(BN7="-",0,BN7*1)) -> 0 | BP7: - | BQ7: - | BR7: - | BS7: =VLOOKUP(BQ7,$A$27:$E$43,2,FALSE)+(IF(BR7="-",0,BR7*1)) -> 0 | BT7: - | BU7: - | BV7: - | BW7: =VLOOKUP(BU7,$A$27:$E$43,2,FALSE)+(IF(BV7="-",0,BV7*1)) -> 0
A8: 46098 | B8: =IF(E8="-",0,1)+IF(I8="-",0,1)+IF(M8="-",0,1)+IF(Q8="-",0,1)+IF(U8="-",0,1)+IF(Y8="-",0,1)+IF(AC8="-",0,1)+IF(AG8="-",0,1)+IF(AK8="-",0,1)+IF(AO8="-",0,1)+IF(AS8="-",0,1)+IF(AW8="-",0,1)+IF(BA8="-",0,1)+IF(BE8="-",0,1)+IF(BI8="-",0,1)+IF(BM8="-",0,1)+IF(BQ8="-",0,1)+IF(BU8="-",0,1) -> 8 | C8: =(B8*$D$44)-IF(B8 >0,30,0) -> 50 | D8: S | E8: 2 | F8: 5 | G8: =VLOOKUP(E8,$A$27:$E$43,2,FALSE)+(IF(F8="-",0,F8*1)) -> 23 | H8: S | I8: 5 | J8: - | K8: =VLOOKUP(I8,$A$27:$E$43,2,FALSE)+(IF(J8="-",0,J8*1)) -> 10 | L8: S | M8: 3 | N8: 1 | O8: =VLOOKUP(M8,$A$27:$E$43,2,FALSE)+(IF(N8="-",0,N8*1)) -> 16 | P8: S | Q8: 7 | R8: - | S8: =VLOOKUP(Q8,$A$27:$E$43,2,FALSE)+(IF(R8="-",0,R8*1)) -> 6 | T8: - | U8: - | V8: - | W8: =VLOOKUP(U8,$A$27:$E$43,2,FALSE)+(IF(V8="-",0,V8*1)) -> 0 | X8: S | Y8: 6 | Z8: - | AA8: =VLOOKUP(Y8,$A$27:$E$43,2,FALSE)+(IF(Z8="-",0,Z8*1)) -> 8 | AB8: S | AC8: 8 | AD8: - | AE8: =VLOOKUP(AC8,$A$27:$E$43,2,FALSE)+(IF(AD8="-",0,AD8*1)) -> 4 | AF8: S | AG8: 4 | AH8: - | AI8: =VLOOKUP(AG8,$A$27:$E$43,2,FALSE)+(IF(AH8="-",0,AH8*1)) -> 12 | AJ8: S | AK8: 1 | AL8: 2 | AM8: =VLOOKUP(AK8,$A$27:$E$43,2,FALSE)+(IF(AL8="-",0,AL8*1)) -> 27 | AN8: - | AO8: - | AP8: - | AQ8: =VLOOKUP(AO8,$A$27:$E$43,2,FALSE)+(IF(AP8="-",0,AP8*1)) -> 0 | AR8: - | AS8: - | AT8: - | AU8: =VLOOKUP(AS8,$A$27:$E$43,2,FALSE)+(IF(AT8="-",0,AT8*1)) -> 0 | AV8: - | AW8: - | AX8: - | AY8: =VLOOKUP(AW8,$A$27:$E$43,2,FALSE)+(IF(AX8="-",0,AX8*1)) -> 0 | AZ8: - | BA8: - | BB8: - | BC8: =VLOOKUP(BA8,$A$27:$E$43,2,FALSE)+(IF(BB8="-",0,BB8*1)) -> 0 | BD8: - | BE8: - | BF8: - | BG8: =VLOOKUP(BE8,$A$27:$E$43,2,FALSE)+(IF(BF8="-",0,BF8*1)) -> 0 | BH8: - | BI8: - | BJ8: - | BK8: =VLOOKUP(BI8,$A$27:$E$43,2,FALSE)+(IF(BJ8="-",0,BJ8*1)) -> 0 | BL8: - | BM8: - | BN8: - | BO8: =VLOOKUP(BM8,$A$27:$E$43,2,FALSE)+(IF(BN8="-",0,BN8*1)) -> 0 | BP8: - | BQ8: - | BR8: - | BS8: =VLOOKUP(BQ8,$A$27:$E$43,2,FALSE)+(IF(BR8="-",0,BR8*1)) -> 0 | BT8: - | BU8: - | BV8: - | BW8: =VLOOKUP(BU8,$A$27:$E$43,2,FALSE)+(IF(BV8="-",0,BV8*1)) -> 0
A9: 46105 | B9: =IF(E9="-",0,1)+IF(I9="-",0,1)+IF(M9="-",0,1)+IF(Q9="-",0,1)+IF(U9="-",0,1)+IF(Y9="-",0,1)+IF(AC9="-",0,1)+IF(AG9="-",0,1)+IF(AK9="-",0,1)+IF(AO9="-",0,1)+IF(AS9="-",0,1)+IF(AW9="-",0,1)+IF(BA9="-",0,1)+IF(BE9="-",0,1)+IF(BI9="-",0,1)+IF(BM9="-",0,1)+IF(BQ9="-",0,1)+IF(BU9="-",0,1) -> 6 | C9: =(B9*$D$44)-IF(B9 >0,30,0) -> 30 | D9: S | E9: 1 | F9: 2 | G9: =VLOOKUP(E9,$A$27:$E$43,2,FALSE)+(IF(F9="-",0,F9*1)) -> 27 | H9: - | I9: - | J9: - | K9: =VLOOKUP(I9,$A$27:$E$43,2,FALSE)+(IF(J9="-",0,J9*1)) -> 0 | L9: - | M9: 5 | N9: - | O9: =VLOOKUP(M9,$A$27:$E$43,2,FALSE)+(IF(N9="-",0,N9*1)) -> 10 | P9: - | Q9: 4 | R9: 1 | S9: =VLOOKUP(Q9,$A$27:$E$43,2,FALSE)+(IF(R9="-",0,R9*1)) -> 13 | T9: S | U9: 2 | V9: 3 | W9: =VLOOKUP(U9,$A$27:$E$43,2,FALSE)+(IF(V9="-",0,V9*1)) -> 21 | X9: - | Y9: - | Z9: - | AA9: =VLOOKUP(Y9,$A$27:$E$43,2,FALSE)+(IF(Z9="-",0,Z9*1)) -> 0 | AB9: S | AC9: 3 | AD9: - | AE9: =VLOOKUP(AC9,$A$27:$E$43,2,FALSE)+(IF(AD9="-",0,AD9*1)) -> 15 | AF9: - | AG9: - | AH9: - | AI9: =VLOOKUP(AG9,$A$27:$E$43,2,FALSE)+(IF(AH9="-",0,AH9*1)) -> 0 | AJ9: S | AK9: 6 | AL9: - | AM9: =VLOOKUP(AK9,$A$27:$E$43,2,FALSE)+(IF(AL9="-",0,AL9*1)) -> 8 | AN9: - | AO9: - | AP9: - | AQ9: =VLOOKUP(AO9,$A$27:$E$43,2,FALSE)+(IF(AP9="-",0,AP9*1)) -> 0 | AR9: - | AS9: - | AT9: - | AU9: =VLOOKUP(AS9,$A$27:$E$43,2,FALSE)+(IF(AT9="-",0,AT9*1)) -> 0 | AV9: - | AW9: - | AX9: - | AY9: =VLOOKUP(AW9,$A$27:$E$43,2,FALSE)+(IF(AX9="-",0,AX9*1)) -> 0 | AZ9: - | BA9: - | BB9: - | BC9: =VLOOKUP(BA9,$A$27:$E$43,2,FALSE)+(IF(BB9="-",0,BB9*1)) -> 0 | BD9: - | BE9: - | BF9: - | BG9: =VLOOKUP(BE9,$A$27:$E$43,2,FALSE)+(IF(BF9="-",0,BF9*1)) -> 0 | BH9: - | BI9: - | BJ9: - | BK9: =VLOOKUP(BI9,$A$27:$E$43,2,FALSE)+(IF(BJ9="-",0,BJ9*1)) -> 0 | BL9: - | BM9: - | BN9: - | BO9: =VLOOKUP(BM9,$A$27:$E$43,2,FALSE)+(IF(BN9="-",0,BN9*1)) -> 0 | BP9: - | BQ9: - | BR9: - | BS9: =VLOOKUP(BQ9,$A$27:$E$43,2,FALSE)+(IF(BR9="-",0,BR9*1)) -> 0 | BT9: - | BU9: - | BV9: - | BW9: =VLOOKUP(BU9,$A$27:$E$43,2,FALSE)+(IF(BV9="-",0,BV9*1)) -> 0
A10: 46112 | B10: =IF(E10="-",0,1)+IF(I10="-",0,1)+IF(M10="-",0,1)+IF(Q10="-",0,1)+IF(U10="-",0,1)+IF(Y10="-",0,1)+IF(AC10="-",0,1)+IF(AG10="-",0,1)+IF(AK10="-",0,1)+IF(AO10="-",0,1)+IF(AS10="-",0,1)+IF(AW10="-",0,1)+IF(BA10="-",0,1)+IF(BE10="-",0,1)+IF(BI10="-",0,1)+IF(BM10="-",0,1)+IF(BQ10="-",0,1)+IF(BU10="-",0,1) -> 8 | C10: =(B10*$D$44)-IF(B10 >0,30,0) -> 50 | D10: - | E10: - | F10: - | G10: =VLOOKUP(E10,$A$27:$E$43,2,FALSE)+(IF(F10="-",0,F10*1)) -> 0 | H10: S | I10: 3 | J10: 2 | K10: =VLOOKUP(I10,$A$27:$E$43,2,FALSE)+(IF(J10="-",0,J10*1)) -> 17 | L10: S | M10: 6 | N10: - | O10: =VLOOKUP(M10,$A$27:$E$43,2,FALSE)+(IF(N10="-",0,N10*1)) -> 8 | P10: S | Q10: 5 | R10: - | S10: =VLOOKUP(Q10,$A$27:$E$43,2,FALSE)+(IF(R10="-",0,R10*1)) -> 10 | T10: S | U10: 1 | V10: 5 | W10: =VLOOKUP(U10,$A$27:$E$43,2,FALSE)+(IF(V10="-",0,V10*1)) -> 30 | X10: S | Y10: 7 | Z10: - | AA10: =VLOOKUP(Y10,$A$27:$E$43,2,FALSE)+(IF(Z10="-",0,Z10*1)) -> 6 | AB10: S | AC10: 8 | AD10: - | AE10: =VLOOKUP(AC10,$A$27:$E$43,2,FALSE)+(IF(AD10="-",0,AD10*1)) -> 4 | AF10: S | AG10: 2 | AH10: 1 | AI10: =VLOOKUP(AG10,$A$27:$E$43,2,FALSE)+(IF(AH10="-",0,AH10*1)) -> 19 | AJ10: S | AK10: 4 | AL10: - | AM10: =VLOOKUP(AK10,$A$27:$E$43,2,FALSE)+(IF(AL10="-",0,AL10*1)) -> 12 | AN10: - | AO10: - | AP10: - | AQ10: =VLOOKUP(AO10,$A$27:$E$43,2,FALSE)+(IF(AP10="-",0,AP10*1)) -> 0 | AR10: - | AS10: - | AT10: - | AU10: =VLOOKUP(AS10,$A$27:$E$43,2,FALSE)+(IF(AT10="-",0,AT10*1)) -> 0 | AV10: - | AW10: - | AX10: - | AY10: =VLOOKUP(AW10,$A$27:$E$43,2,FALSE)+(IF(AX10="-",0,AX10*1)) -> 0 | AZ10: - | BA10: - | BB10: - | BC10: =VLOOKUP(BA10,$A$27:$E$43,2,FALSE)+(IF(BB10="-",0,BB10*1)) -> 0 | BD10: - | BE10: - | BF10: - | BG10: =VLOOKUP(BE10,$A$27:$E$43,2,FALSE)+(IF(BF10="-",0,BF10*1)) -> 0 | BH10: - | BI10: - | BJ10: - | BK10: =VLOOKUP(BI10,$A$27:$E$43,2,FALSE)+(IF(BJ10="-",0,BJ10*1)) -> 0 | BL10: - | BM10: - | BN10: - | BO10: =VLOOKUP(BM10,$A$27:$E$43,2,FALSE)+(IF(BN10="-",0,BN10*1)) -> 0 | BP10: - | BQ10: - | BR10: - | BS10: =VLOOKUP(BQ10,$A$27:$E$43,2,FALSE)+(IF(BR10="-",0,BR10*1)) -> 0 | BT10: - | BU10: - | BV10: - | BW10: =VLOOKUP(BU10,$A$27:$E$43,2,FALSE)+(IF(BV10="-",0,BV10*1)) -> 0
A11: 46119 | B11: =IF(E11="-",0,1)+IF(I11="-",0,1)+IF(M11="-",0,1)+IF(Q11="-",0,1)+IF(U11="-",0,1)+IF(Y11="-",0,1)+IF(AC11="-",0,1)+IF(AG11="-",0,1)+IF(AK11="-",0,1)+IF(AO11="-",0,1)+IF(AS11="-",0,1)+IF(AW11="-",0,1)+IF(BA11="-",0,1)+IF(BE11="-",0,1)+IF(BI11="-",0,1)+IF(BM11="-",0,1)+IF(BQ11="-",0,1)+IF(BU11="-",0,1) -> 9 | C11: =(B11*$D$44)-IF(B11 >0,30,0) -> 60 | D11: S | E11: 3 | F11: - | G11: =VLOOKUP(E11,$A$27:$E$43,2,FALSE)+(IF(F11="-",0,F11*1)) -> 15 | H11: S | I11: 9 | J11: - | K11: =VLOOKUP(I11,$A$27:$E$43,2,FALSE)+(IF(J11="-",0,J11*1)) -> 2 | L11: S | M11: 1 | N11: 3 | O11: =VLOOKUP(M11,$A$27:$E$43,2,FALSE)+(IF(N11="-",0,N11*1)) -> 28 | P11: S | Q11: 5 | R11: - | S11: =VLOOKUP(Q11,$A$27:$E$43,2,FALSE)+(IF(R11="-",0,R11*1)) -> 10 | T11: S | U11: 4 | V11: 2 | W11: =VLOOKUP(U11,$A$27:$E$43,2,FALSE)+(IF(V11="-",0,V11*1)) -> 14 | X11: S | Y11: 2 | Z11: 2 | AA11: =VLOOKUP(Y11,$A$27:$E$43,2,FALSE)+(IF(Z11="-",0,Z11*1)) -> 20 | AB11: S | AC11: 8 | AD11: - | AE11: =VLOOKUP(AC11,$A$27:$E$43,2,FALSE)+(IF(AD11="-",0,AD11*1)) -> 4 | AF11: S | AG11: 7 | AH11: - | AI11: =VLOOKUP(AG11,$A$27:$E$43,2,FALSE)+(IF(AH11="-",0,AH11*1)) -> 6 | AJ11: S | AK11: 6 | AL11: - | AM11: =VLOOKUP(AK11,$A$27:$E$43,2,FALSE)+(IF(AL11="-",0,AL11*1)) -> 8 | AN11: - | AO11: - | AP11: - | AQ11: =VLOOKUP(AO11,$A$27:$E$43,2,FALSE)+(IF(AP11="-",0,AP11*1)) -> 0 | AR11: - | AS11: - | AT11: - | AU11: =VLOOKUP(AS11,$A$27:$E$43,2,FALSE)+(IF(AT11="-",0,AT11*1)) -> 0 | AV11: - | AW11: - | AX11: - | AY11: =VLOOKUP(AW11,$A$27:$E$43,2,FALSE)+(IF(AX11="-",0,AX11*1)) -> 0 | AZ11: - | BA11: - | BB11: - | BC11: =VLOOKUP(BA11,$A$27:$E$43,2,FALSE)+(IF(BB11="-",0,BB11*1)) -> 0 | BD11: - | BE11: - | BF11: - | BG11: =VLOOKUP(BE11,$A$27:$E$43,2,FALSE)+(IF(BF11="-",0,BF11*1)) -> 0 | BH11: - | BI11: - | BJ11: - | BK11: =VLOOKUP(BI11,$A$27:$E$43,2,FALSE)+(IF(BJ11="-",0,BJ11*1)) -> 0 | BL11: - | BM11: - | BN11: - | BO11: =VLOOKUP(BM11,$A$27:$E$43,2,FALSE)+(IF(BN11="-",0,BN11*1)) -> 0 | BP11: - | BQ11: - | BR11: - | BS11: =VLOOKUP(BQ11,$A$27:$E$43,2,FALSE)+(IF(BR11="-",0,BR11*1)) -> 0 | BT11: - | BU11: - | BV11: - | BW11: =VLOOKUP(BU11,$A$27:$E$43,2,FALSE)+(IF(BV11="-",0,BV11*1)) -> 0
A12: 46126 | B12: =IF(E12="-",0,1)+IF(I12="-",0,1)+IF(M12="-",0,1)+IF(Q12="-",0,1)+IF(U12="-",0,1)+IF(Y12="-",0,1)+IF(AC12="-",0,1)+IF(AG12="-",0,1)+IF(AK12="-",0,1)+IF(AO12="-",0,1)+IF(AS12="-",0,1)+IF(AW12="-",0,1)+IF(BA12="-",0,1)+IF(BE12="-",0,1)+IF(BI12="-",0,1)+IF(BM12="-",0,1)+IF(BQ12="-",0,1)+IF(BU12="-",0,1) -> 8 | C12: =(B12*$D$44)-IF(B12 >0,30,0) -> 50 | D12: - | E12: 1 | F12: 3 | G12: =VLOOKUP(E12,$A$27:$E$43,2,FALSE)+(IF(F12="-",0,F12*1)) -> 28 | H12: S | I12: 8 | J12: - | K12: =VLOOKUP(I12,$A$27:$E$43,2,FALSE)+(IF(J12="-",0,J12*1)) -> 4 | L12: S | M12: 6 | N12: - | O12: =VLOOKUP(M12,$A$27:$E$43,2,FALSE)+(IF(N12="-",0,N12*1)) -> 8 | P12: - | Q12: 3 | R12: 1 | S12: =VLOOKUP(Q12,$A$27:$E$43,2,FALSE)+(IF(R12="-",0,R12*1)) -> 16 | T12: S | U12: 2 | V12: 4 | W12: =VLOOKUP(U12,$A$27:$E$43,2,FALSE)+(IF(V12="-",0,V12*1)) -> 22 | X12: S | Y12: 7 | Z12: - | AA12: =VLOOKUP(Y12,$A$27:$E$43,2,FALSE)+(IF(Z12="-",0,Z12*1)) -> 6 | AB12: S | AC12: 4 | AD12: - | AE12: =VLOOKUP(AC12,$A$27:$E$43,2,FALSE)+(IF(AD12="-",0,AD12*1)) -> 12 | AF12: - | AG12: - | AH12: - | AI12: =VLOOKUP(AG12,$A$27:$E$43,2,FALSE)+(IF(AH12="-",0,AH12*1)) -> 0 | AJ12: - | AK12: 5 | AL12: - | AM12: =VLOOKUP(AK12,$A$27:$E$43,2,FALSE)+(IF(AL12="-",0,AL12*1)) -> 10 | AN12: - | AO12: - | AP12: - | AQ12: =VLOOKUP(AO12,$A$27:$E$43,2,FALSE)+(IF(AP12="-",0,AP12*1)) -> 0 | AR12: - | AS12: - | AT12: - | AU12: =VLOOKUP(AS12,$A$27:$E$43,2,FALSE)+(IF(AT12="-",0,AT12*1)) -> 0 | AV12: - | AW12: - | AX12: - | AY12: =VLOOKUP(AW12,$A$27:$E$43,2,FALSE)+(IF(AX12="-",0,AX12*1)) -> 0 | AZ12: - | BA12: - | BB12: - | BC12: =VLOOKUP(BA12,$A$27:$E$43,2,FALSE)+(IF(BB12="-",0,BB12*1)) -> 0 | BD12: - | BE12: - | BF12: - | BG12: =VLOOKUP(BE12,$A$27:$E$43,2,FALSE)+(IF(BF12="-",0,BF12*1)) -> 0 | BH12: - | BI12: - | BJ12: - | BK12: =VLOOKUP(BI12,$A$27:$E$43,2,FALSE)+(IF(BJ12="-",0,BJ12*1)) -> 0 | BL12: - | BM12: - | BN12: - | BO12: =VLOOKUP(BM12,$A$27:$E$43,2,FALSE)+(IF(BN12="-",0,BN12*1)) -> 0 | BP12: - | BQ12: - | BR12: - | BS12: =VLOOKUP(BQ12,$A$27:$E$43,2,FALSE)+(IF(BR12="-",0,BR12*1)) -> 0 | BT12: - | BU12: - | BV12: - | BW12: =VLOOKUP(BU12,$A$27:$E$43,2,FALSE)+(IF(BV12="-",0,BV12*1)) -> 0
A13: 46133 | B13: =IF(E13="-",0,1)+IF(I13="-",0,1)+IF(M13="-",0,1)+IF(Q13="-",0,1)+IF(U13="-",0,1)+IF(Y13="-",0,1)+IF(AC13="-",0,1)+IF(AG13="-",0,1)+IF(AK13="-",0,1)+IF(AO13="-",0,1)+IF(AS13="-",0,1)+IF(AW13="-",0,1)+IF(BA13="-",0,1)+IF(BE13="-",0,1)+IF(BI13="-",0,1)+IF(BM13="-",0,1)+IF(BQ13="-",0,1)+IF(BU13="-",0,1) -> 0 | C13: =(B13*$D$44)-IF(B13 >0,30,0) -> 0 | D13: - | E13: - | F13: - | G13: =VLOOKUP(E13,$A$27:$E$43,2,FALSE)+(IF(F13="-",0,F13*1)) -> 0 | H13: - | I13: - | J13: - | K13: =VLOOKUP(I13,$A$27:$E$43,2,FALSE)+(IF(J13="-",0,J13*1)) -> 0 | L13: - | M13: - | N13: - | O13: =VLOOKUP(M13,$A$27:$E$43,2,FALSE)+(IF(N13="-",0,N13*1)) -> 0 | P13: - | Q13: - | R13: - | S13: =VLOOKUP(Q13,$A$27:$E$43,2,FALSE)+(IF(R13="-",0,R13*1)) -> 0 | T13: - | U13: - | V13: - | W13: =VLOOKUP(U13,$A$27:$E$43,2,FALSE)+(IF(V13="-",0,V13*1)) -> 0 | X13: - | Y13: - | Z13: - | AA13: =VLOOKUP(Y13,$A$27:$E$43,2,FALSE)+(IF(Z13="-",0,Z13*1)) -> 0 | AB13: - | AC13: - | AD13: - | AE13: =VLOOKUP(AC13,$A$27:$E$43,2,FALSE)+(IF(AD13="-",0,AD13*1)) -> 0 | AF13: - | AG13: - | AH13: - | AI13: =VLOOKUP(AG13,$A$27:$E$43,2,FALSE)+(IF(AH13="-",0,AH13*1)) -> 0 | AJ13: - | AK13: - | AL13: - | AM13: =VLOOKUP(AK13,$A$27:$E$43,2,FALSE)+(IF(AL13="-",0,AL13*1)) -> 0 | AN13: - | AO13: - | AP13: - | AQ13: =VLOOKUP(AO13,$A$27:$E$43,2,FALSE)+(IF(AP13="-",0,AP13*1)) -> 0 | AR13: - | AS13: - | AT13: - | AU13: =VLOOKUP(AS13,$A$27:$E$43,2,FALSE)+(IF(AT13="-",0,AT13*1)) -> 0 | AV13: - | AW13: - | AX13: - | AY13: =VLOOKUP(AW13,$A$27:$E$43,2,FALSE)+(IF(AX13="-",0,AX13*1)) -> 0 | AZ13: - | BA13: - | BB13: - | BC13: =VLOOKUP(BA13,$A$27:$E$43,2,FALSE)+(IF(BB13="-",0,BB13*1)) -> 0 | BD13: - | BE13: - | BF13: - | BG13: =VLOOKUP(BE13,$A$27:$E$43,2,FALSE)+(IF(BF13="-",0,BF13*1)) -> 0 | BH13: - | BI13: - | BJ13: - | BK13: =VLOOKUP(BI13,$A$27:$E$43,2,FALSE)+(IF(BJ13="-",0,BJ13*1)) -> 0 | BL13: - | BM13: - | BN13: - | BO13: =VLOOKUP(BM13,$A$27:$E$43,2,FALSE)+(IF(BN13="-",0,BN13*1)) -> 0 | BP13: - | BQ13: - | BR13: - | BS13: =VLOOKUP(BQ13,$A$27:$E$43,2,FALSE)+(IF(BR13="-",0,BR13*1)) -> 0 | BT13: - | BU13: - | BV13: - | BW13: =VLOOKUP(BU13,$A$27:$E$43,2,FALSE)+(IF(BV13="-",0,BV13*1)) -> 0
A14: 46140 | B14: =IF(E14="-",0,1)+IF(I14="-",0,1)+IF(M14="-",0,1)+IF(Q14="-",0,1)+IF(U14="-",0,1)+IF(Y14="-",0,1)+IF(AC14="-",0,1)+IF(AG14="-",0,1)+IF(AK14="-",0,1)+IF(AO14="-",0,1)+IF(AS14="-",0,1)+IF(AW14="-",0,1)+IF(BA14="-",0,1)+IF(BE14="-",0,1)+IF(BI14="-",0,1)+IF(BM14="-",0,1)+IF(BQ14="-",0,1)+IF(BU14="-",0,1) -> 8 | C14: =(B14*$D$44)-IF(B14 >0,30,0) -> 50 | D14: S | E14: 8 | F14: - | G14: =VLOOKUP(E14,$A$27:$E$43,2,FALSE)+(IF(F14="-",0,F14*1)) -> 4 | H14: S | I14: 2 | J14: 1 | K14: =VLOOKUP(I14,$A$27:$E$43,2,FALSE)+(IF(J14="-",0,J14*1)) -> 19 | L14: S | M14: 5 | N14: - | O14: =VLOOKUP(M14,$A$27:$E$43,2,FALSE)+(IF(N14="-",0,N14*1)) -> 10 | P14: S | Q14: 4 | R14: 1 | S14: =VLOOKUP(Q14,$A$27:$E$43,2,FALSE)+(IF(R14="-",0,R14*1)) -> 13 | T14: S | U14: 1 | V14: 4 | W14: =VLOOKUP(U14,$A$27:$E$43,2,FALSE)+(IF(V14="-",0,V14*1)) -> 29 | X14: S | Y14: 3 | Z14: 2 | AA14: =VLOOKUP(Y14,$A$27:$E$43,2,FALSE)+(IF(Z14="-",0,Z14*1)) -> 17 | AB14: S | AC14: 6 | AD14: - | AE14: =VLOOKUP(AC14,$A$27:$E$43,2,FALSE)+(IF(AD14="-",0,AD14*1)) -> 8 | AF14: - | AG14: - | AH14: - | AI14: =VLOOKUP(AG14,$A$27:$E$43,2,FALSE)+(IF(AH14="-",0,AH14*1)) -> 0 | AJ14: S | AK14: 7 | AL14: - | AM14: =VLOOKUP(AK14,$A$27:$E$43,2,FALSE)+(IF(AL14="-",0,AL14*1)) -> 6 | AN14: - | AO14: - | AP14: - | AQ14: =VLOOKUP(AO14,$A$27:$E$43,2,FALSE)+(IF(AP14="-",0,AP14*1)) -> 0 | AR14: - | AS14: - | AT14: - | AU14: =VLOOKUP(AS14,$A$27:$E$43,2,FALSE)+(IF(AT14="-",0,AT14*1)) -> 0 | AV14: - | AW14: - | AX14: - | AY14: =VLOOKUP(AW14,$A$27:$E$43,2,FALSE)+(IF(AX14="-",0,AX14*1)) -> 0 | AZ14: - | BA14: - | BB14: - | BC14: =VLOOKUP(BA14,$A$27:$E$43,2,FALSE)+(IF(BB14="-",0,BB14*1)) -> 0 | BD14: - | BE14: - | BF14: - | BG14: =VLOOKUP(BE14,$A$27:$E$43,2,FALSE)+(IF(BF14="-",0,BF14*1)) -> 0 | BH14: - | BI14: - | BJ14: - | BK14: =VLOOKUP(BI14,$A$27:$E$43,2,FALSE)+(IF(BJ14="-",0,BJ14*1)) -> 0 | BL14: - | BM14: - | BN14: - | BO14: =VLOOKUP(BM14,$A$27:$E$43,2,FALSE)+(IF(BN14="-",0,BN14*1)) -> 0 | BP14: - | BQ14: - | BR14: - | BS14: =VLOOKUP(BQ14,$A$27:$E$43,2,FALSE)+(IF(BR14="-",0,BR14*1)) -> 0 | BT14: - | BU14: - | BV14: - | BW14: =VLOOKUP(BU14,$A$27:$E$43,2,FALSE)+(IF(BV14="-",0,BV14*1)) -> 0
A15: 46147 | B15: =IF(E15="-",0,1)+IF(I15="-",0,1)+IF(M15="-",0,1)+IF(Q15="-",0,1)+IF(U15="-",0,1)+IF(Y15="-",0,1)+IF(AC15="-",0,1)+IF(AG15="-",0,1)+IF(AK15="-",0,1)+IF(AO15="-",0,1)+IF(AS15="-",0,1)+IF(AW15="-",0,1)+IF(BA15="-",0,1)+IF(BE15="-",0,1)+IF(BI15="-",0,1)+IF(BM15="-",0,1)+IF(BQ15="-",0,1)+IF(BU15="-",0,1) -> 9 | C15: =(B15*$D$44)-IF(B15 >0,30,0) -> 60 | D15: S | E15: 2 | F15: 3 | G15: =VLOOKUP(E15,$A$27:$E$43,2,FALSE)+(IF(F15="-",0,F15*1)) -> 21 | H15: S | I15: 8 | J15: - | K15: =VLOOKUP(I15,$A$27:$E$43,2,FALSE)+(IF(J15="-",0,J15*1)) -> 4 | L15: S | M15: 1 | N15: 4 | O15: =VLOOKUP(M15,$A$27:$E$43,2,FALSE)+(IF(N15="-",0,N15*1)) -> 29 | P15: S | Q15: 9 | R15: - | S15: =VLOOKUP(Q15,$A$27:$E$43,2,FALSE)+(IF(R15="-",0,R15*1)) -> 2 | T15: S | U15: 4 | V15: 1 | W15: =VLOOKUP(U15,$A$27:$E$43,2,FALSE)+(IF(V15="-",0,V15*1)) -> 13 | X15: S | Y15: 3 | Z15: - | AA15: =VLOOKUP(Y15,$A$27:$E$43,2,FALSE)+(IF(Z15="-",0,Z15*1)) -> 15 | AB15: S | AC15: 6 | AD15: - | AE15: =VLOOKUP(AC15,$A$27:$E$43,2,FALSE)+(IF(AD15="-",0,AD15*1)) -> 8 | AF15: S | AG15: 7 | AH15: - | AI15: =VLOOKUP(AG15,$A$27:$E$43,2,FALSE)+(IF(AH15="-",0,AH15*1)) -> 6 | AJ15: S | AK15: 5 | AL15: 1 | AM15: =VLOOKUP(AK15,$A$27:$E$43,2,FALSE)+(IF(AL15="-",0,AL15*1)) -> 11 | AN15: - | AO15: - | AP15: - | AQ15: =VLOOKUP(AO15,$A$27:$E$43,2,FALSE)+(IF(AP15="-",0,AP15*1)) -> 0 | AR15: - | AS15: - | AT15: - | AU15: =VLOOKUP(AS15,$A$27:$E$43,2,FALSE)+(IF(AT15="-",0,AT15*1)) -> 0 | AV15: - | AW15: - | AX15: - | AY15: =VLOOKUP(AW15,$A$27:$E$43,2,FALSE)+(IF(AX15="-",0,AX15*1)) -> 0 | AZ15: - | BA15: - | BB15: - | BC15: =VLOOKUP(BA15,$A$27:$E$43,2,FALSE)+(IF(BB15="-",0,BB15*1)) -> 0 | BD15: - | BE15: - | BF15: - | BG15: =VLOOKUP(BE15,$A$27:$E$43,2,FALSE)+(IF(BF15="-",0,BF15*1)) -> 0 | BH15: - | BI15: - | BJ15: - | BK15: =VLOOKUP(BI15,$A$27:$E$43,2,FALSE)+(IF(BJ15="-",0,BJ15*1)) -> 0 | BL15: - | BM15: - | BN15: - | BO15: =VLOOKUP(BM15,$A$27:$E$43,2,FALSE)+(IF(BN15="-",0,BN15*1)) -> 0 | BP15: - | BQ15: - | BR15: - | BS15: =VLOOKUP(BQ15,$A$27:$E$43,2,FALSE)+(IF(BR15="-",0,BR15*1)) -> 0 | BT15: - | BU15: - | BV15: - | BW15: =VLOOKUP(BU15,$A$27:$E$43,2,FALSE)+(IF(BV15="-",0,BV15*1)) -> 0
A16: 46154 | B16: =IF(E16="-",0,1)+IF(I16="-",0,1)+IF(M16="-",0,1)+IF(Q16="-",0,1)+IF(U16="-",0,1)+IF(Y16="-",0,1)+IF(AC16="-",0,1)+IF(AG16="-",0,1)+IF(AK16="-",0,1)+IF(AO16="-",0,1)+IF(AS16="-",0,1)+IF(AW16="-",0,1)+IF(BA16="-",0,1)+IF(BE16="-",0,1)+IF(BI16="-",0,1)+IF(BM16="-",0,1)+IF(BQ16="-",0,1)+IF(BU16="-",0,1) -> 8 | C16: =(B16*$D$44)-IF(B16 >0,30,0) -> 50 | D16: S | E16: 3 | F16: 2 | G16: =VLOOKUP(E16,$A$27:$E$43,2,FALSE)+(IF(F16="-",0,F16*1)) -> 17 | H16: S | I16: 6 | J16: - | K16: =VLOOKUP(I16,$A$27:$E$43,2,FALSE)+(IF(J16="-",0,J16*1)) -> 8 | L16: A | M16: 1 | N16: 3 | O16: =VLOOKUP(M16,$A$27:$E$43,2,FALSE)+(IF(N16="-",0,N16*1)) -> 28 | P16: - | Q16: - | R16: - | S16: =VLOOKUP(Q16,$A$27:$E$43,2,FALSE)+(IF(R16="-",0,R16*1)) -> 0 | T16: S | U16: 2 | V16: 2 | W16: =VLOOKUP(U16,$A$27:$E$43,2,FALSE)+(IF(V16="-",0,V16*1)) -> 20 | X16: S | Y16: 7 | Z16: - | AA16: =VLOOKUP(Y16,$A$27:$E$43,2,FALSE)+(IF(Z16="-",0,Z16*1)) -> 6 | AB16: - | AC16: - | AD16: - | AE16: =VLOOKUP(AC16,$A$27:$E$43,2,FALSE)+(IF(AD16="-",0,AD16*1)) -> 0 | AF16: S | AG16: 4 | AH16: - | AI16: =VLOOKUP(AG16,$A$27:$E$43,2,FALSE)+(IF(AH16="-",0,AH16*1)) -> 12 | AJ16: S | AK16: 8 | AL16: - | AM16: =VLOOKUP(AK16,$A$27:$E$43,2,FALSE)+(IF(AL16="-",0,AL16*1)) -> 4 | AN16: - | AO16: - | AP16: - | AQ16: =VLOOKUP(AO16,$A$27:$E$43,2,FALSE)+(IF(AP16="-",0,AP16*1)) -> 0 | AR16: - | AS16: - | AT16: - | AU16: =VLOOKUP(AS16,$A$27:$E$43,2,FALSE)+(IF(AT16="-",0,AT16*1)) -> 0 | AV16: S | AW16: 5 | AX16: 1 | AY16: =VLOOKUP(AW16,$A$27:$E$43,2,FALSE)+(IF(AX16="-",0,AX16*1)) -> 11 | AZ16: - | BA16: - | BB16: - | BC16: =VLOOKUP(BA16,$A$27:$E$43,2,FALSE)+(IF(BB16="-",0,BB16*1)) -> 0 | BD16: - | BE16: - | BF16: - | BG16: =VLOOKUP(BE16,$A$27:$E$43,2,FALSE)+(IF(BF16="-",0,BF16*1)) -> 0 | BH16: - | BI16: - | BJ16: - | BK16: =VLOOKUP(BI16,$A$27:$E$43,2,FALSE)+(IF(BJ16="-",0,BJ16*1)) -> 0 | BL16: - | BM16: - | BN16: - | BO16: =VLOOKUP(BM16,$A$27:$E$43,2,FALSE)+(IF(BN16="-",0,BN16*1)) -> 0 | BP16: - | BQ16: - | BR16: - | BS16: =VLOOKUP(BQ16,$A$27:$E$43,2,FALSE)+(IF(BR16="-",0,BR16*1)) -> 0 | BT16: - | BU16: - | BV16: - | BW16: =VLOOKUP(BU16,$A$27:$E$43,2,FALSE)+(IF(BV16="-",0,BV16*1)) -> 0
A17: 46161 | B17: =IF(E17="-",0,1)+IF(I17="-",0,1)+IF(M17="-",0,1)+IF(Q17="-",0,1)+IF(U17="-",0,1)+IF(Y17="-",0,1)+IF(AC17="-",0,1)+IF(AG17="-",0,1)+IF(AK17="-",0,1)+IF(AO17="-",0,1)+IF(AS17="-",0,1)+IF(AW17="-",0,1)+IF(BA17="-",0,1)+IF(BE17="-",0,1)+IF(BI17="-",0,1)+IF(BM17="-",0,1)+IF(BQ17="-",0,1)+IF(BU17="-",0,1) -> 8 | C17: =(B17*$D$44)-IF(B17 >0,30,0) -> 50 | E17: 6 | F17: - | G17: =VLOOKUP(E17,$A$27:$E$43,2,FALSE)+(IF(F17="-",0,F17*1)) -> 8 | H17: S | I17: 1 | J17: 3 | K17: =VLOOKUP(I17,$A$27:$E$43,2,FALSE)+(IF(J17="-",0,J17*1)) -> 28 | L17: S | M17: 2 | N17: 1 | O17: =VLOOKUP(M17,$A$27:$E$43,2,FALSE)+(IF(N17="-",0,N17*1)) -> 19 | P17: - | Q17: - | R17: - | S17: =VLOOKUP(Q17,$A$27:$E$43,2,FALSE)+(IF(R17="-",0,R17*1)) -> 0 | T17: S | U17: 5 | V17: - | W17: =VLOOKUP(U17,$A$27:$E$43,2,FALSE)+(IF(V17="-",0,V17*1)) -> 10 | Y17: 4 | Z17: 2 | AA17: =VLOOKUP(Y17,$A$27:$E$43,2,FALSE)+(IF(Z17="-",0,Z17*1)) -> 14 | AB17: S | AC17: 3 | AD17: 2 | AE17: =VLOOKUP(AC17,$A$27:$E$43,2,FALSE)+(IF(AD17="-",0,AD17*1)) -> 17 | AF17: S | AG17: 8 | AH17: - | AI17: =VLOOKUP(AG17,$A$27:$E$43,2,FALSE)+(IF(AH17="-",0,AH17*1)) -> 4 | AJ17: - | AK17: - | AL17: - | AM17: =VLOOKUP(AK17,$A$27:$E$43,2,FALSE)+(IF(AL17="-",0,AL17*1)) -> 0 | AN17: - | AO17: - | AP17: - | AQ17: =VLOOKUP(AO17,$A$27:$E$43,2,FALSE)+(IF(AP17="-",0,AP17*1)) -> 0 | AR17: - | AS17: - | AT17: - | AU17: =VLOOKUP(AS17,$A$27:$E$43,2,FALSE)+(IF(AT17="-",0,AT17*1)) -> 0 | AV17: S | AW17: 7 | AX17: - | AY17: =VLOOKUP(AW17,$A$27:$E$43,2,FALSE)+(IF(AX17="-",0,AX17*1)) -> 6 | AZ17: - | BA17: - | BB17: - | BC17: =VLOOKUP(BA17,$A$27:$E$43,2,FALSE)+(IF(BB17="-",0,BB17*1)) -> 0 | BD17: - | BE17: - | BF17: - | BG17: =VLOOKUP(BE17,$A$27:$E$43,2,FALSE)+(IF(BF17="-",0,BF17*1)) -> 0 | BH17: - | BI17: - | BJ17: - | BK17: =VLOOKUP(BI17,$A$27:$E$43,2,FALSE)+(IF(BJ17="-",0,BJ17*1)) -> 0 | BL17: - | BM17: - | BN17: - | BO17: =VLOOKUP(BM17,$A$27:$E$43,2,FALSE)+(IF(BN17="-",0,BN17*1)) -> 0 | BP17: - | BQ17: - | BR17: - | BS17: =VLOOKUP(BQ17,$A$27:$E$43,2,FALSE)+(IF(BR17="-",0,BR17*1)) -> 0 | BT17: - | BU17: - | BV17: - | BW17: =VLOOKUP(BU17,$A$27:$E$43,2,FALSE)+(IF(BV17="-",0,BV17*1)) -> 0
A18: 46168 | B18: =IF(E18="-",0,1)+IF(I18="-",0,1)+IF(M18="-",0,1)+IF(Q18="-",0,1)+IF(U18="-",0,1)+IF(Y18="-",0,1)+IF(AC18="-",0,1)+IF(AG18="-",0,1)+IF(AK18="-",0,1)+IF(AO18="-",0,1)+IF(AS18="-",0,1)+IF(AW18="-",0,1)+IF(BA18="-",0,1)+IF(BE18="-",0,1)+IF(BI18="-",0,1)+IF(BM18="-",0,1)+IF(BQ18="-",0,1)+IF(BU18="-",0,1) -> 9 | C18: =(B18*$D$44)-IF(B18 >0,30,0) -> 60 | D18: S | E18: 5 | F18: 1 | G18: =VLOOKUP(E18,$A$27:$E$43,2,FALSE)+(IF(F18="-",0,F18*1)) -> 11 | H18: S | I18: 4 | J18: 1 | K18: =VLOOKUP(I18,$A$27:$E$43,2,FALSE)+(IF(J18="-",0,J18*1)) -> 13 | L18: S | M18: 6 | N18: - | O18: =VLOOKUP(M18,$A$27:$E$43,2,FALSE)+(IF(N18="-",0,N18*1)) -> 8 | P18: S | Q18: 1 | R18: 3 | S18: =VLOOKUP(Q18,$A$27:$E$43,2,FALSE)+(IF(R18="-",0,R18*1)) -> 28 | T18: S | U18: 8 | V18: - | W18: =VLOOKUP(U18,$A$27:$E$43,2,FALSE)+(IF(V18="-",0,V18*1)) -> 4 | X18: - | Y18: - | Z18: - | AA18: =VLOOKUP(Y18,$A$27:$E$43,2,FALSE)+(IF(Z18="-",0,Z18*1)) -> 0 | AB18: S | AC18: 9 | AD18: - | AE18: =VLOOKUP(AC18,$A$27:$E$43,2,FALSE)+(IF(AD18="-",0,AD18*1)) -> 2 | AF18: S | AG18: 3 | AH18: 1 | AI18: =VLOOKUP(AG18,$A$27:$E$43,2,FALSE)+(IF(AH18="-",0,AH18*1)) -> 16 | AJ18: S | AK18: 2 | AL18: 2 | AM18: =VLOOKUP(AK18,$A$27:$E$43,2,FALSE)+(IF(AL18="-",0,AL18*1)) -> 20 | AN18: - | AO18: - | AP18: - | AQ18: =VLOOKUP(AO18,$A$27:$E$43,2,FALSE)+(IF(AP18="-",0,AP18*1)) -> 0 | AR18: - | AS18: - | AT18: - | AU18: =VLOOKUP(AS18,$A$27:$E$43,2,FALSE)+(IF(AT18="-",0,AT18*1)) -> 0 | AV18: S | AW18: 7 | AX18: - | AY18: =VLOOKUP(AW18,$A$27:$E$43,2,FALSE)+(IF(AX18="-",0,AX18*1)) -> 6 | AZ18: - | BA18: - | BB18: - | BC18: =VLOOKUP(BA18,$A$27:$E$43,2,FALSE)+(IF(BB18="-",0,BB18*1)) -> 0 | BD18: - | BE18: - | BF18: - | BG18: =VLOOKUP(BE18,$A$27:$E$43,2,FALSE)+(IF(BF18="-",0,BF18*1)) -> 0 | BH18: - | BI18: - | BJ18: - | BK18: =VLOOKUP(BI18,$A$27:$E$43,2,FALSE)+(IF(BJ18="-",0,BJ18*1)) -> 0 | BL18: - | BM18: - | BN18: - | BO18: =VLOOKUP(BM18,$A$27:$E$43,2,FALSE)+(IF(BN18="-",0,BN18*1)) -> 0 | BP18: - | BQ18: - | BR18: - | BS18: =VLOOKUP(BQ18,$A$27:$E$43,2,FALSE)+(IF(BR18="-",0,BR18*1)) -> 0 | BT18: - | BU18: - | BV18: - | BW18: =VLOOKUP(BU18,$A$27:$E$43,2,FALSE)+(IF(BV18="-",0,BV18*1)) -> 0
A19: 46175 | B19: =IF(E19="-",0,1)+IF(I19="-",0,1)+IF(M19="-",0,1)+IF(Q19="-",0,1)+IF(U19="-",0,1)+IF(Y19="-",0,1)+IF(AC19="-",0,1)+IF(AG19="-",0,1)+IF(AK19="-",0,1)+IF(AO19="-",0,1)+IF(AS19="-",0,1)+IF(AW19="-",0,1)+IF(BA19="-",0,1)+IF(BE19="-",0,1)+IF(BI19="-",0,1)+IF(BM19="-",0,1)+IF(BQ19="-",0,1)+IF(BU19="-",0,1) -> 9 | C19: =(B19*$D$44)-IF(B19 >0,30,0) -> 60 | D19: S | E19: 1 | F19: 4 | G19: =VLOOKUP(E19,$A$27:$E$43,2,FALSE)+(IF(F19="-",0,F19*1)) -> 29 | H19: S | I19: 9 | J19: - | K19: =VLOOKUP(I19,$A$27:$E$43,2,FALSE)+(IF(J19="-",0,J19*1)) -> 2 | L19: S | M19: 7 | N19: - | O19: =VLOOKUP(M19,$A$27:$E$43,2,FALSE)+(IF(N19="-",0,N19*1)) -> 6 | P19: S | Q19: 3 | R19: - | S19: =VLOOKUP(Q19,$A$27:$E$43,2,FALSE)+(IF(R19="-",0,R19*1)) -> 15 | T19: S | U19: 2 | V19: 3 | W19: =VLOOKUP(U19,$A$27:$E$43,2,FALSE)+(IF(V19="-",0,V19*1)) -> 21 | X19: S | Y19: 8 | Z19: - | AA19: =VLOOKUP(Y19,$A$27:$E$43,2,FALSE)+(IF(Z19="-",0,Z19*1)) -> 4 | AB19: S | AC19: 5 | AD19: 2 | AE19: =VLOOKUP(AC19,$A$27:$E$43,2,FALSE)+(IF(AD19="-",0,AD19*1)) -> 12 | AF19: S | AG19: 6 | AH19: - | AI19: =VLOOKUP(AG19,$A$27:$E$43,2,FALSE)+(IF(AH19="-",0,AH19*1)) -> 8 | AJ19: S | AK19: 4 | AL19: - | AM19: =VLOOKUP(AK19,$A$27:$E$43,2,FALSE)+(IF(AL19="-",0,AL19*1)) -> 12 | AN19: - | AO19: - | AP19: - | AQ19: =VLOOKUP(AO19,$A$27:$E$43,2,FALSE)+(IF(AP19="-",0,AP19*1)) -> 0 | AR19: - | AS19: - | AT19: - | AU19: =VLOOKUP(AS19,$A$27:$E$43,2,FALSE)+(IF(AT19="-",0,AT19*1)) -> 0 | AV19: - | AW19: - | AX19: - | AY19: =VLOOKUP(AW19,$A$27:$E$43,2,FALSE)+(IF(AX19="-",0,AX19*1)) -> 0 | AZ19: - | BA19: - | BB19: - | BC19: =VLOOKUP(BA19,$A$27:$E$43,2,FALSE)+(IF(BB19="-",0,BB19*1)) -> 0 | BD19: - | BE19: - | BF19: - | BG19: =VLOOKUP(BE19,$A$27:$E$43,2,FALSE)+(IF(BF19="-",0,BF19*1)) -> 0 | BH19: - | BI19: - | BJ19: - | BK19: =VLOOKUP(BI19,$A$27:$E$43,2,FALSE)+(IF(BJ19="-",0,BJ19*1)) -> 0 | BL19: - | BM19: - | BN19: - | BO19: =VLOOKUP(BM19,$A$27:$E$43,2,FALSE)+(IF(BN19="-",0,BN19*1)) -> 0 | BP19: - | BQ19: - | BR19: - | BS19: =VLOOKUP(BQ19,$A$27:$E$43,2,FALSE)+(IF(BR19="-",0,BR19*1)) -> 0 | BT19: - | BU19: - | BV19: - | BW19: =VLOOKUP(BU19,$A$27:$E$43,2,FALSE)+(IF(BV19="-",0,BV19*1)) -> 0
A20: 46182 | B20: =IF(E20="-",0,1)+IF(I20="-",0,1)+IF(M20="-",0,1)+IF(Q20="-",0,1)+IF(U20="-",0,1)+IF(Y20="-",0,1)+IF(AC20="-",0,1)+IF(AG20="-",0,1)+IF(AK20="-",0,1)+IF(AO20="-",0,1)+IF(AS20="-",0,1)+IF(AW20="-",0,1)+IF(BA20="-",0,1)+IF(BE20="-",0,1)+IF(BI20="-",0,1)+IF(BM20="-",0,1)+IF(BQ20="-",0,1)+IF(BU20="-",0,1) -> 8 | C20: =(B20*$D$44)-IF(B20 >0,30,0) -> 50 | D20: - | E20: 3 | F20: - | G20: =VLOOKUP(E20,$A$27:$E$43,2,FALSE)+(IF(F20="-",0,F20*1)) -> 15 | H20: - | I20: 2 | J20: 4 | K20: =VLOOKUP(I20,$A$27:$E$43,2,FALSE)+(IF(J20="-",0,J20*1)) -> 22 | L20: - | M20: 5 | N20: 1 | O20: =VLOOKUP(M20,$A$27:$E$43,2,FALSE)+(IF(N20="-",0,N20*1)) -> 11 | P20: - | Q20: 1 | R20: 3 | S20: =VLOOKUP(Q20,$A$27:$E$43,2,FALSE)+(IF(R20="-",0,R20*1)) -> 28 | T20: - | U20: 4 | V20: - | W20: =VLOOKUP(U20,$A$27:$E$43,2,FALSE)+(IF(V20="-",0,V20*1)) -> 12 | X20: - | Y20: 6 | Z20: - | AA20: =VLOOKUP(Y20,$A$27:$E$43,2,FALSE)+(IF(Z20="-",0,Z20*1)) -> 8 | AB20: - | AC20: 7 | AD20: - | AE20: =VLOOKUP(AC20,$A$27:$E$43,2,FALSE)+(IF(AD20="-",0,AD20*1)) -> 6 | AF20: - | AG20: - | AH20: - | AI20: =VLOOKUP(AG20,$A$27:$E$43,2,FALSE)+(IF(AH20="-",0,AH20*1)) -> 0 | AJ20: - | AK20: - | AL20: - | AM20: =VLOOKUP(AK20,$A$27:$E$43,2,FALSE)+(IF(AL20="-",0,AL20*1)) -> 0 | AN20: - | AO20: - | AP20: - | AQ20: =VLOOKUP(AO20,$A$27:$E$43,2,FALSE)+(IF(AP20="-",0,AP20*1)) -> 0 | AR20: - | AS20: - | AT20: - | AU20: =VLOOKUP(AS20,$A$27:$E$43,2,FALSE)+(IF(AT20="-",0,AT20*1)) -> 0 | AV20: - | AW20: 8 | AX20: - | AY20: =VLOOKUP(AW20,$A$27:$E$43,2,FALSE)+(IF(AX20="-",0,AX20*1)) -> 4 | AZ20: - | BA20: - | BB20: - | BC20: =VLOOKUP(BA20,$A$27:$E$43,2,FALSE)+(IF(BB20="-",0,BB20*1)) -> 0 | BD20: - | BE20: - | BF20: - | BG20: =VLOOKUP(BE20,$A$27:$E$43,2,FALSE)+(IF(BF20="-",0,BF20*1)) -> 0 | BH20: - | BI20: - | BJ20: - | BK20: =VLOOKUP(BI20,$A$27:$E$43,2,FALSE)+(IF(BJ20="-",0,BJ20*1)) -> 0 | BL20: - | BM20: - | BN20: - | BO20: =VLOOKUP(BM20,$A$27:$E$43,2,FALSE)+(IF(BN20="-",0,BN20*1)) -> 0 | BP20: - | BQ20: - | BR20: - | BS20: =VLOOKUP(BQ20,$A$27:$E$43,2,FALSE)+(IF(BR20="-",0,BR20*1)) -> 0 | BT20: - | BU20: - | BV20: - | BW20: =VLOOKUP(BU20,$A$27:$E$43,2,FALSE)+(IF(BV20="-",0,BV20*1)) -> 0
A21: TOTAL | B21: MESA | C21: =SUM(C3:C20)-39 -> 881 | E21: =IFERROR(MEDIAN(E3:E20),0) -> 3 | F21: =IFERROR(SUM(F3:F20),0) -> 29 | G21: =IFERROR(SUM(G3:G20),0) -> 279 | I21: =IFERROR(MEDIAN(I3:I20),0) -> 5.5 | J21: =IFERROR(SUM(J3:J20),0) -> 14 | K21: =IFERROR(SUM(K3:K20),0) -> 170 | M21: =IFERROR(MEDIAN(M3:M20),0) -> 5 | N21: =IFERROR(SUM(N3:N20),0) -> 18 | O21: =IFERROR(SUM(O3:O20),0) -> 255 | Q21: =IFERROR(MEDIAN(Q3:Q20),0) -> 4 | R21: =IFERROR(SUM(R3:R20),0) -> 17 | S21: =IFERROR(SUM(S3:S20),0) -> 223 | U21: =IFERROR(MEDIAN(U3:U20),0) -> 4 | V21: =IFERROR(SUM(V3:V20),0) -> 25 | W21: =IFERROR(SUM(W3:W20),0) -> 233 | Y21: =IFERROR(MEDIAN(Y3:Y20),0) -> 6 | Z21: =IFERROR(SUM(Z3:Z20),0) -> 7 | AA21: =IFERROR(SUM(AA3:AA20),0) -> 133 | AC21: =IFERROR(MEDIAN(AC3:AC20),0) -> 6.5 | AD21: =IFERROR(SUM(AD3:AD20),0) -> 8 | AE21: =IFERROR(SUM(AE3:AE20),0) -> 129 | AG21: =IFERROR(MEDIAN(AG3:AG20),0) -> 4 | AH21: =IFERROR(SUM(AH3:AH20),0) -> 9 | AI21: =IFERROR(SUM(AI3:AI20),0) -> 165 | AK21: =IFERROR(MEDIAN(AK3:AK20),0) -> 5 | AL21: =IFERROR(SUM(AL3:AL20),0) -> 11 | AM21: =IFERROR(SUM(AM3:AM20),0) -> 184 | AO21: =IFERROR(MEDIAN(AO3:AO20),0) -> 0 | AP21: =IFERROR(SUM(AP3:AP20),0) -> 0 | AQ21: =IFERROR(SUM(AQ3:AQ20),0) -> 0 | AS21: =IFERROR(MEDIAN(AS3:AS20),0) -> 2 | AT21: =IFERROR(SUM(AT3:AT20),0) -> 2 | AU21: =IFERROR(SUM(AU3:AU20),0) -> 20 | AW21: =IFERROR(MEDIAN(AW3:AW20),0) -> 7 | AX21: =IFERROR(SUM(AX3:AX20),0) -> 1 | AY21: =IFERROR(SUM(AY3:AY20),0) -> 27 | BA21: =IFERROR(MEDIAN(BA3:BA20),0) -> 0 | BB21: =IFERROR(SUM(BB3:BB20),0) -> 0 | BC21: =IFERROR(SUM(BC3:BC20),0) -> 0 | BE21: =IFERROR(MEDIAN(BE3:BE20),0) -> 0 | BF21: =IFERROR(SUM(BF3:BF20),0) -> 0 | BG21: =IFERROR(SUM(BG3:BG20),0) -> 0 | BI21: =IFERROR(MEDIAN(BI3:BI20),0) -> 0 | BJ21: =IFERROR(SUM(BJ3:BJ20),0) -> 0 | BK21: =IFERROR(SUM(BK3:BK20),0) -> 0 | BM21: =IFERROR(MEDIAN(BM3:BM20),0) -> 0 | BN21: =IFERROR(SUM(BN3:BN20),0) -> 0 | BO21: =IFERROR(SUM(BO3:BO20),0) -> 0 | BQ21: =IFERROR(MEDIAN(BQ3:BQ20),0) -> 0 | BR21: =IFERROR(SUM(BR3:BR20),0) -> 0 | BS21: =IFERROR(SUM(BS3:BS20),0) -> 0 | BU21: =IFERROR(MEDIAN(BU3:BU20),0) -> 0 | BV21: =IFERROR(SUM(BV3:BV20),0) -> 0 | BW21: =IFERROR(SUM(BW3:BW20),0) -> 0
A22: 02/04/26 Retirando do caixa R$39,00 para compra de um novo baralho
A25: PARAMETROS | H25: RANKING PONTUAÇÃO | T25: RANKING CARRASCO | AG25: Blinds | AO25: Fichas iniciais | AS25: =AO27*AR27+AO28*AR28+AO29*AR29+AO30*AR30+AO31*AR31+BA33*BD33 -> 10000
A26: POSIÇÃO | B26: TOTAL DE PONTOS | E26: PREMIAÇÂO | H26: POSIÇÃO | J26: PONTOS | M26: PARTICIPANTE | T26: POSIÇÃO | V26: ALMAS | Y26: PARTICIPANTE | AG26: 1 | AH26: 0.83333333 | AJ26: 100 | AL26: =AJ26/2 -> 50 | AO26: Valor | AR26: Quantidade
A27: 1 | B27: 25 | D27: 20 | H27: 1 | J27: =VLOOKUP(H27,AUX!$A$2:$C$19,3,false) -> 279 | M27: =VLOOKUP(H27,AUX!$A$2:$C$19,2,FALSE) -> SERGIO | T27: 1 | V27: =VLOOKUP(T27,AUX!$E$2:$G$19,3,false) -> 29 | Y27: =VLOOKUP(T27,AUX!$E$2:$G$19,2,FALSE) -> SERGIO | AG27: 2 | AH27: 0.84722222 | AJ27: 200 | AL27: =AJ27/2 -> 100 | AO27: 50 | AR27: 10
A28: 2 | B28: 18 | D28: 10 | H28: 2 | J28: =VLOOKUP(H28,AUX!$A$2:$C$19,3,false) -> 255 | M28: =VLOOKUP(H28,AUX!$A$2:$C$19,2,FALSE) -> DANILO | T28: 2 | V28: =VLOOKUP(T28,AUX!$E$2:$G$19,3,false) -> 25 | Y28: =VLOOKUP(T28,AUX!$E$2:$G$19,2,FALSE) -> NINO | AG28: 3 | AH28: 0.86111111 | AJ28: 300 | AL28: =AJ28/2 -> 150 | AO28: 100 | AR28: 10
A29: 3 | B29: 15 | D29: 0 | H29: 3 | J29: =VLOOKUP(H29,AUX!$A$2:$C$19,3,false) -> 233 | M29: =VLOOKUP(H29,AUX!$A$2:$C$19,2,FALSE) -> NINO | T29: 3 | V29: =VLOOKUP(T29,AUX!$E$2:$G$19,3,false) -> 18 | Y29: =VLOOKUP(T29,AUX!$E$2:$G$19,2,FALSE) -> DANILO | AG29: 4 | AH29: 0.875 | AJ29: 400 | AL29: =AJ29/2 -> 200 | AO29: 500 | AR29: 3
A30: 4 | B30: 12 | D30: 0 | H30: 4 | J30: =VLOOKUP(H30,AUX!$A$2:$C$19,3,false) -> 223 | M30: =VLOOKUP(H30,AUX!$A$2:$C$19,2,FALSE) -> EDINHO | T30: 4 | V30: =VLOOKUP(T30,AUX!$E$2:$G$19,3,false) -> 17 | Y30: =VLOOKUP(T30,AUX!$E$2:$G$19,2,FALSE) -> EDINHO | AG30: 5 | AH30: 0.88888889 | AJ30: 600 | AL30: =AJ30/2 -> 300 | AO30: 1000 | AR30: 2
A31: 5 | B31: 10 | D31: 0 | H31: 5 | J31: =VLOOKUP(H31,AUX!$A$2:$C$19,3,false) -> 184 | M31: =VLOOKUP(H31,AUX!$A$2:$C$19,2,FALSE) -> UEDA | T31: 5 | V31: =VLOOKUP(T31,AUX!$E$2:$G$19,3,false) -> 14 | Y31: =VLOOKUP(T31,AUX!$E$2:$G$19,2,FALSE) -> FELIPE | AG31: 6 | AH31: 0.90277778 | AJ31: 1000 | AL31: =AJ31/2 -> 500 | AO31: 5000 | AR31: 1
A32: 6 | B32: 8 | D32: 0 | H32: 6 | J32: =VLOOKUP(H32,AUX!$A$2:$C$19,3,false) -> 170 | M32: =VLOOKUP(H32,AUX!$A$2:$C$19,2,FALSE) -> FELIPE | T32: 6 | V32: =VLOOKUP(T32,AUX!$E$2:$G$19,3,false) -> 11 | Y32: =VLOOKUP(T32,AUX!$E$2:$G$19,2,FALSE) -> UEDA | AG32: 7 | AH32: 0.91666667 | AJ32: 1500 | AL32: =AJ32/2 -> 750
A33: 7 | B33: 6 | D33: 0 | H33: 7 | J33: =VLOOKUP(H33,AUX!$A$2:$C$19,3,false) -> 165 | M33: =VLOOKUP(H33,AUX!$A$2:$C$19,2,FALSE) -> ENIO | T33: 7 | V33: =VLOOKUP(T33,AUX!$E$2:$G$19,3,false) -> 9 | Y33: =VLOOKUP(T33,AUX!$E$2:$G$19,2,FALSE) -> ENIO | AG33: 8 | AH33: 0.93055556 | AJ33: 2000 | AL33: =AJ33/2 -> 1000
A34: 8 | B34: 4 | D34: 0 | H34: 8 | J34: =VLOOKUP(H34,AUX!$A$2:$C$19,3,false) -> 133 | M34: =VLOOKUP(H34,AUX!$A$2:$C$19,2,FALSE) -> CARLÃO | T34: 8 | V34: =VLOOKUP(T34,AUX!$E$2:$G$19,3,false) -> 8 | Y34: =VLOOKUP(T34,AUX!$E$2:$G$19,2,FALSE) -> GRANDE | AG34: 9 | AH34: 0.94444444 | AJ34: 3000 | AL34: =AJ34/2 -> 1500
A35: 9 | B35: 2 | D35: 0 | H35: 9 | J35: =VLOOKUP(H35,AUX!$A$2:$C$19,3,false) -> 129 | M35: =VLOOKUP(H35,AUX!$A$2:$C$19,2,FALSE) -> GRANDE | T35: 9 | V35: =VLOOKUP(T35,AUX!$E$2:$G$19,3,false) -> 7 | Y35: =VLOOKUP(T35,AUX!$E$2:$G$19,2,FALSE) -> CARLÃO | AG35: 10 | AH35: 0.95833333 | AJ35: 4000 | AL35: =AJ35/2 -> 2000
A36: 10 | B36: 1 | D36: 0 | H36: 10 | J36: =VLOOKUP(H36,AUX!$A$2:$C$19,3,false) -> 27 | M36: =VLOOKUP(H36,AUX!$A$2:$C$19,2,FALSE) -> ALEXANDRE | T36: 10 | V36: =VLOOKUP(T36,AUX!$E$2:$G$19,3,false) -> 2 | Y36: =VLOOKUP(T36,AUX!$E$2:$G$19,2,FALSE) -> TURATI | AG36: 11 | AH36: 0.97222222 | AJ36: 5000 | AL36: =AJ36/2 -> 2500
A37: 11 | B37: 1 | D37: 0 | H37: 11 | J37: =VLOOKUP(H37,AUX!$A$2:$C$19,3,false) -> 20 | M37: =VLOOKUP(H37,AUX!$A$2:$C$19,2,FALSE) -> TURATI | T37: 11 | V37: =VLOOKUP(T37,AUX!$E$2:$G$19,3,false) -> 1 | Y37: =VLOOKUP(T37,AUX!$E$2:$G$19,2,FALSE) -> ALEXANDRE | AG37: 12 | AH37: 0.98611111 | AJ37: 6000 | AL37: =AJ37/2 -> 3000
A38: 12 | B38: 1 | D38: 0 | H38: 12 | J38: =VLOOKUP(H38,AUX!$A$2:$C$19,3,false) -> 0 | M38: =VLOOKUP(H38,AUX!$A$2:$C$19,2,FALSE) -> MICA | T38: 12 | V38: =VLOOKUP(H38,AUX!$E$2:$G$19,3,false) -> 0 | Y38: =VLOOKUP(T38,AUX!$A$2:$C$19,2,FALSE) -> MICA | AG38: 13 | AH38: 1 | AJ38: 10000 | AL38: =AJ38/2 -> 5000
A39: 13 | B39: 1 | D39: 0 | H39: 13 | J39: =VLOOKUP(H39,AUX!$A$2:$C$19,3,false) -> 0 | M39: =VLOOKUP(H39,AUX!$A$2:$C$19,2,FALSE) -> - | T39: 13 | V39: =VLOOKUP(H39,AUX!$E$2:$G$19,3,false) -> 0 | Y39: =VLOOKUP(T39,AUX!$A$2:$C$19,2,FALSE) -> -
A40: 14 | B40: 1 | D40: 0 | H40: 14 | J40: =VLOOKUP(H40,AUX!$A$2:$C$19,3,false) -> 0 | M40: =VLOOKUP(H40,AUX!$A$2:$C$19,2,FALSE) -> - | T40: 14 | V40: =VLOOKUP(H40,AUX!$E$2:$G$19,3,false) -> 0 | Y40: =VLOOKUP(T40,AUX!$A$2:$C$19,2,FALSE) -> -
A41: 15 | B41: 1 | D41: 0 | H41: 15 | J41: =VLOOKUP(H41,AUX!$A$2:$C$19,3,false) -> 0 | M41: =VLOOKUP(H41,AUX!$A$2:$C$19,2,FALSE) -> - | T41: 15 | V41: =VLOOKUP(H41,AUX!$E$2:$G$19,3,false) -> 0 | Y41: =VLOOKUP(T41,AUX!$A$2:$C$19,2,FALSE) -> -
A42: - | B42: 0 | D42: 0 | H42: 16 | J42: =VLOOKUP(H42,AUX!$A$2:$C$19,3,false) -> 0 | M42: =VLOOKUP(H42,AUX!$A$2:$C$19,2,FALSE) -> - | T42: 16 | V42: =VLOOKUP(H42,AUX!$E$2:$G$19,3,false) -> 0 | Y42: =VLOOKUP(T42,AUX!$A$2:$C$19,2,FALSE) -> -
...

Sheet AUX
A1: POSIÇÃO | B1: PARTICIPANTE | C1: PONTOS | E1: POSIÇÃO | F1: PARTICIPANTE | G1: ALMAS
A2: =_xlfn.RANK.EQ(C2,$C$2:$C$19,FALSE)+COUNTIF($C$2:C2,C2)-1 -> 1 | B2: =PONTUACAO!D1 -> SERGIO | C2: =PONTUACAO!G21 -> 279 | E2: =RANK(G2,$G$2:$G$19,FALSE)+COUNTIF($G$2:G2,G2)-1 -> 1 | F2: =PONTUACAO!D1 -> SERGIO | G2: =PONTUACAO!F21 -> 29 | I2: =PONTUACAO!K1
A3: =_xlfn.RANK.EQ(C3,$C$2:$C$19,FALSE)+COUNTIF($C$2:C3,C3)-1 -> 6 | B3: =PONTUACAO!H1 -> FELIPE | C3: =PONTUACAO!K21 -> 170 | E3: =RANK(G3,$G$2:$G$19,FALSE)+COUNTIF($G$2:G3,G3)-1 -> 5 | F3: =PONTUACAO!H1 -> FELIPE | G3: =PONTUACAO!J21 -> 14 | I3: =PONTUACAO!O1
A4: =_xlfn.RANK.EQ(C4,$C$2:$C$19,FALSE)+COUNTIF($C$2:C4,C4)-1 -> 2 | B4: =PONTUACAO!L1 -> DANILO | C4: =PONTUACAO!O21 -> 255 | E4: =RANK(G4,$G$2:$G$19,FALSE)+COUNTIF($G$2:G4,G4)-1 -> 3 | F4: =PONTUACAO!L1 -> DANILO | G4: =PONTUACAO!N21 -> 18 | I4: =PONTUACAO!S1
A5: =_xlfn.RANK.EQ(C5,$C$2:$C$19,FALSE)+COUNTIF($C$2:C5,C5)-1 -> 4 | B5: =PONTUACAO!P1 -> EDINHO | C5: =PONTUACAO!S21 -> 223 | E5: =RANK(G5,$G$2:$G$19,FALSE)+COUNTIF($G$2:G5,G5)-1 -> 4 | F5: =PONTUACAO!P1 -> EDINHO | G5: =PONTUACAO!R21 -> 17 | I5: =PONTUACAO!W1
A6: =_xlfn.RANK.EQ(C6,$C$2:$C$19,FALSE)+COUNTIF($C$2:C6,C6)-1 -> 3 | B6: =PONTUACAO!T1 -> NINO | C6: =PONTUACAO!W21 -> 233 | E6: =RANK(G6,$G$2:$G$19,FALSE)+COUNTIF($G$2:G6,G6)-1 -> 2 | F6: =PONTUACAO!T1 -> NINO | G6: =PONTUACAO!V21 -> 25 | I6: =PONTUACAO!AA1
A7: =_xlfn.RANK.EQ(C7,$C$2:$C$19,FALSE)+COUNTIF($C$2:C7,C7)-1 -> 8 | B7: =PONTUACAO!X1 -> CARLÃO | C7: =PONTUACAO!AA21 -> 133 | E7: =RANK(G7,$G$2:$G$19,FALSE)+COUNTIF($G$2:G7,G7)-1 -> 9 | F7: =PONTUACAO!X1 -> CARLÃO | G7: =PONTUACAO!Z21 -> 7 | I7: =PONTUACAO!AE1
A8: =_xlfn.RANK.EQ(C8,$C$2:$C$19,FALSE)+COUNTIF($C$2:C8,C8)-1 -> 9 | B8: =PONTUACAO!AB1 -> GRANDE | C8: =PONTUACAO!AE21 -> 129 | E8: =RANK(G8,$G$2:$G$19,FALSE)+COUNTIF($G$2:G8,G8)-1 -> 8 | F8: =PONTUACAO!AB1 -> GRANDE | G8: =PONTUACAO!AD21 -> 8 | I8: =PONTUACAO!AI1
A9: =_xlfn.RANK.EQ(C9,$C$2:$C$19,FALSE)+COUNTIF($C$2:C9,C9)-1 -> 7 | B9: =PONTUACAO!AF1 -> ENIO | C9: =PONTUACAO!AI21 -> 165 | E9: =RANK(G9,$G$2:$G$19,FALSE)+COUNTIF($G$2:G9,G9)-1 -> 7 | F9: =PONTUACAO!AF1 -> ENIO | G9: =PONTUACAO!AH21 -> 9 | I9: =PONTUACAO!AM1
A10: =_xlfn.RANK.EQ(C10,$C$2:$C$19,FALSE)+COUNTIF($C$2:C10,C10)-1 -> 5 | B10: =PONTUACAO!AJ1 -> UEDA | C10: =PONTUACAO!AM21 -> 184 | E10: =RANK(G10,$G$2:$G$19,FALSE)+COUNTIF($G$2:G10,G10)-1 -> 6 | F10: =PONTUACAO!AJ1 -> UEDA | G10: =PONTUACAO!AL21 -> 11 | I10: =PONTUACAO!AQ1
A11: =_xlfn.RANK.EQ(C11,$C$2:$C$19,FALSE)+COUNTIF($C$2:C11,C11)-1 -> 12 | B11: =PONTUACAO!AN1 -> MICA | C11: =PONTUACAO!AQ21 -> 0 | E11: =RANK(G11,$G$2:$G$19,FALSE)+COUNTIF($G$2:G11,G11)-1 -> 12 | F11: =PONTUACAO!AN1 -> MICA | G11: =PONTUACAO!AP21 -> 0 | I11: =PONTUACAO!AU1
A12: =_xlfn.RANK.EQ(C12,$C$2:$C$19,FALSE)+COUNTIF($C$2:C12,C12)-1 -> 11 | B12: =PONTUACAO!AR1 -> TURATI | C12: =PONTUACAO!AU21 -> 20 | E12: =RANK(G12,$G$2:$G$19,FALSE)+COUNTIF($G$2:G12,G12)-1 -> 10 | F12: =PONTUACAO!AR1 -> TURATI | G12: =PONTUACAO!AT21 -> 2 | I12: =PONTUACAO!AY1
A13: =_xlfn.RANK.EQ(C13,$C$2:$C$19,FALSE)+COUNTIF($C$2:C13,C13)-1 -> 10 | B13: =PONTUACAO!AV1 -> ALEXANDRE | C13: =PONTUACAO!AY21 -> 27 | E13: =RANK(G13,$G$2:$G$19,FALSE)+COUNTIF($G$2:G13,G13)-1 -> 11 | F13: =PONTUACAO!AV1 -> ALEXANDRE | G13: =PONTUACAO!AX21 -> 1 | I13: =PONTUACAO!BC1
A14: =_xlfn.RANK.EQ(C14,$C$2:$C$19,FALSE)+COUNTIF($C$2:C14,C14)-1 -> 13 | B14: =PONTUACAO!AZ1 -> - | C14: =PONTUACAO!BC21 -> 0 | E14: =RANK(G14,$G$2:$G$19,FALSE)+COUNTIF($G$2:G14,G14)-1 -> 13 | F14: =PONTUACAO!D13 -> - | G14: =PONTUACAO!BB21 -> 0 | I14: =PONTUACAO!BG1
A15: =_xlfn.RANK.EQ(C15,$C$2:$C$19,FALSE)+COUNTIF($C$2:C15,C15)-1 -> 14 | B15: =PONTUACAO!BD1 -> - | C15: =PONTUACAO!BG21 -> 0 | E15: =RANK(G15,$G$2:$G$19,FALSE)+COUNTIF($G$2:G15,G15)-1 -> 14 | F15: =PONTUACAO!H13 -> - | G15: =PONTUACAO!BF21 -> 0 | I15: =PONTUACAO!BK1
A16: =_xlfn.RANK.EQ(C16,$C$2:$C$19,FALSE)+COUNTIF($C$2:C16,C16)-1 -> 15 | B16: =PONTUACAO!BH1 -> - | C16: =PONTUACAO!BK21 -> 0 | E16: =RANK(G16,$G$2:$G$19,FALSE)+COUNTIF($G$2:G16,G16)-1 -> 15 | F16: =PONTUACAO!L13 -> - | G16: =PONTUACAO!BJ21 -> 0 | I16: =PONTUACAO!BO1
A17: =_xlfn.RANK.EQ(C17,$C$2:$C$19,FALSE)+COUNTIF($C$2:C17,C17)-1 -> 16 | B17: =PONTUACAO!BL1 -> - | C17: =PONTUACAO!BO21 -> 0 | E17: =RANK(G17,$G$2:$G$19,FALSE)+COUNTIF($G$2:G17,G17)-1 -> 16 | F17: =PONTUACAO!BP1 -> - | G17: =PONTUACAO!BN21 -> 0 | I17: =PONTUACAO!BS1
A18: =_xlfn.RANK.EQ(C18,$C$2:$C$19,FALSE)+COUNTIF($C$2:C18,C18)-1 -> 17 | B18: =PONTUACAO!BP1 -> - | C18: =PONTUACAO!BS21 -> 0 | E18: =RANK(G18,$G$2:$G$19,FALSE)+COUNTIF($G$2:G18,G18)-1 -> 17 | F18: =PONTUACAO!BT1 -> - | G18: =PONTUACAO!BR21 -> 0 | I18: =PONTUACAO!BW1
A19: =_xlfn.RANK.EQ(C19,$C$2:$C$19,FALSE)+COUNTIF($C$2:C19,C19)-1 -> 18 | B19: =PONTUACAO!BT1 -> - | C19: =PONTUACAO!BW21 -> 0 | E19: =RANK(G19,$G$2:$G$19,FALSE)+COUNTIF($G$2:G19,G19)-1 -> 18 | F19: =PONTUACAO!BX1 | G19: =PONTUACAO!BV21 -> 0 | I19: =PONTUACAO!CA1
